Workbook

Sheet Complaint Log
A1: PEREPA EDU — Customer Complaint Data Capture (Packaging Ink)
A2: 40 logged customer complaints, Apr-Sep 2026
A4: Complaint ID | B4: Date Received | C4: Customer | D4: Product/SKU | E4: Ink Batch | F4: Substrate | G4: Complaint Category | H4: Severity | I4: Status | J4: Resolution Days | K4: Credit Note (INR)
A5: CMP-001 | B5: 46116 | C5: Fresh Dairy Co | D5: SKU-A Snack Pouch | E5: INK-2204 | F5: BOPP | G5: Odor/Taint | H5: Critical | I5: Closed | J5: 9 | K5: 58296
A6: CMP-002 | B6: 46150 | C6: PetNutrition India | D6: SKU-A Snack Pouch | E6: INK-2201 | F6: BOPP | G6: Adhesion/Delamination | H6: Minor | I6: Closed | J6: 8 | K6: 0
A7: CMP-003 | B7: 46143 | C7: Bharat Snacks Ltd | D7: SKU-B Pet Food Pouch | E7: INK-2203 | F7: BOPP | G7: Adhesion/Delamination | H7: Major | I7: Closed | J7: 9 | K7: 23784
A8: CMP-004 | B8: 46168 | C8: Fresh Dairy Co | D8: SKU-C Detergent Pouch | E8: INK-2205 | F8: BOPP | G8: Viscosity/Print Defect | H8: Minor | I8: Closed | J8: 8 | K8: 0
A9: CMP-005 | B9: 46120 | C9: Bharat Snacks Ltd | D9: SKU-C Detergent Pouch | E9: INK-2205 | F9: PET | G9: Odor/Taint | H9: Major | I9: Closed | J9: 25 | K9: 34082
A10: CMP-006 | B10: 46162 | C10: CleanCare Chemicals | D10: SKU-C Detergent Pouch | E10: INK-2202 | F10: PET | G10: Adhesion/Delamination | H10: Major | I10: Closed | J10: 14 | K10: 41576
A11: CMP-007 | B11: 46278 | C11: PetNutrition India | D11: SKU-B Pet Food Pouch | E11: INK-2202 | F11: PE | G11: Viscosity/Print Defect | H11: Minor | I11: Closed | J11: 7 | K11: 6586
A12: CMP-008 | B12: 46252 | C12: PetNutrition India | D12: SKU-B Pet Food Pouch | E12: INK-2201 | F12: BOPP | G12: Adhesion/Delamination | H12: Minor | I12: Closed | J12: 24 | K12: 2783
A13: CMP-009 | B13: 46215 | C13: CleanCare Chemicals | D13: SKU-B Pet Food Pouch | E13: INK-2202 | F13: BOPP | G13: Color Mismatch | H13: Minor | I13: Closed | J13: 3 | K13: 6601
A14: CMP-010 | B14: 46143 | C14: CleanCare Chemicals | D14: SKU-A Snack Pouch | E14: INK-2201 | F14: BOPP | G14: Adhesion/Delamination | H14: Critical | I14: Open | K14: 59906
A15: CMP-011 | B15: 46234 | C15: Bharat Snacks Ltd | D15: SKU-B Pet Food Pouch | E15: INK-2205 | F15: PE | G15: Adhesion/Delamination | H15: Major | I15: Closed | J15: 22 | K15: 12495
A16: CMP-012 | B16: 46141 | C16: Fresh Dairy Co | D16: SKU-A Snack Pouch | E16: INK-2205 | F16: PE | G16: Color Mismatch | H16: Minor | I16: Closed | J16: 17 | K16: 0
A17: CMP-013 | B17: 46202 | C17: Nutri Foods Pvt Ltd | D17: SKU-A Snack Pouch | E17: INK-2201 | F17: PET | G17: Odor/Taint | H17: Major | I17: Open | K17: 18660
A18: CMP-014 | B18: 46144 | C18: SpiceKing Foods | D18: SKU-C Detergent Pouch | E18: INK-2201 | F18: PE | G18: Migration/Compliance Query | H18: Minor | I18: Open | K18: 4447
A19: CMP-015 | B19: 46160 | C19: SpiceKing Foods | D19: SKU-B Pet Food Pouch | E19: INK-2205 | F19: PE | G19: Color Mismatch | H19: Minor | I19: Closed | J19: 9 | K19: 0
A20: CMP-016 | B20: 46270 | C20: Fresh Dairy Co | D20: SKU-B Pet Food Pouch | E20: INK-2204 | F20: PET | G20: Adhesion/Delamination | H20: Critical | I20: Closed | J20: 25 | K20: 65106
A21: CMP-017 | B21: 46187 | C21: PetNutrition India | D21: SKU-B Pet Food Pouch | E21: INK-2205 | F21: BOPP | G21: Adhesion/Delamination | H21: Minor | I21: Closed | J21: 8 | K21: 0
A22: CMP-018 | B22: 46210 | C22: CleanCare Chemicals | D22: SKU-A Snack Pouch | E22: INK-2204 | F22: PE | G22: Adhesion/Delamination | H22: Major | I22: Open | K22: 27658
A23: CMP-019 | B23: 46122 | C23: Bharat Snacks Ltd | D23: SKU-B Pet Food Pouch | E23: INK-2205 | F23: PET | G23: Adhesion/Delamination | H23: Major | I23: Open | K23: 33847
A24: CMP-020 | B24: 46166 | C24: Fresh Dairy Co | D24: SKU-A Snack Pouch | E24: INK-2204 | F24: PET | G24: Print Smudge/Scuff | H24: Major | I24: Closed | J24: 11 | K24: 34133
A25: CMP-021 | B25: 46141 | C25: Nutri Foods Pvt Ltd | D25: SKU-A Snack Pouch | E25: INK-2202 | F25: PE | G25: Odor/Taint | H25: Minor | I25: Closed | J25: 22 | K25: 4272
A26: CMP-022 | B26: 46159 | C26: Fresh Dairy Co | D26: SKU-A Snack Pouch | E26: INK-2201 | F26: PET | G26: Adhesion/Delamination | H26: Minor | I26: Open | K26: 0
A27: CMP-023 | B27: 46210 | C27: CleanCare Chemicals | D27: SKU-B Pet Food Pouch | E27: INK-2203 | F27: BOPP | G27: Odor/Taint | H27: Major | I27: Closed | J27: 9 | K27: 25665
A28: CMP-024 | B28: 46267 | C28: Nutri Foods Pvt Ltd | D28: SKU-C Detergent Pouch | E28: INK-2205 | F28: PET | G28: Print Smudge/Scuff | H28: Minor | I28: Closed | J28: 2 | K28: 5057
A29: CMP-025 | B29: 46239 | C29: CleanCare Chemicals | D29: SKU-C Detergent Pouch | E29: INK-2204 | F29: PE | G29: Migration/Compliance Query | H29: Major | I29: Closed | J29: 14 | K29: 23990
A30: CMP-026 | B30: 46254 | C30: Nutri Foods Pvt Ltd | D30: SKU-B Pet Food Pouch | E30: INK-2201 | F30: PE | G30: Adhesion/Delamination | H30: Minor | I30: Closed | J30: 15 | K30: 0
A31: CMP-027 | B31: 46182 | C31: Bharat Snacks Ltd | D31: SKU-C Detergent Pouch | E31: INK-2201 | F31: PET | G31: Adhesion/Delamination | H31: Major | I31: Open | K31: 19220
A32: CMP-028 | B32: 46125 | C32: CleanCare Chemicals | D32: SKU-B Pet Food Pouch | E32: INK-2201 | F32: PET | G32: Adhesion/Delamination | H32: Minor | I32: Closed | J32: 4 | K32: 0
A33: CMP-029 | B33: 46234 | C33: Fresh Dairy Co | D33: SKU-B Pet Food Pouch | E33: INK-2204 | F33: PET | G33: Odor/Taint | H33: Critical | I33: Closed | J33: 25 | K33: 84416
A34: CMP-030 | B34: 46173 | C34: Nutri Foods Pvt Ltd | D34: SKU-A Snack Pouch | E34: INK-2204 | F34: PET | G34: Adhesion/Delamination | H34: Major | I34: Open | K34: 31119
A35: CMP-031 | B35: 46271 | C35: Fresh Dairy Co | D35: SKU-A Snack Pouch | E35: INK-2204 | F35: BOPP | G35: Migration/Compliance Query | H35: Minor | I35: Open | K35: 2318
A36: CMP-032 | B36: 46218 | C36: Fresh Dairy Co | D36: SKU-B Pet Food Pouch | E36: INK-2202 | F36: PE | G36: Print Smudge/Scuff | H36: Minor | I36: Closed | J36: 12 | K36: 0
A37: CMP-033 | B37: 46255 | C37: CleanCare Chemicals | D37: SKU-A Snack Pouch | E37: INK-2204 | F37: BOPP | G37: Adhesion/Delamination | H37: Major | I37: Open | K37: 22855
A38: CMP-034 | B38: 46145 | C38: PetNutrition India | D38: SKU-B Pet Food Pouch | E38: INK-2204 | F38: BOPP | G38: Adhesion/Delamination | H38: Major | I38: Open | K38: 30526
A39: CMP-035 | B39: 46182 | C39: SpiceKing Foods | D39: SKU-B Pet Food Pouch | E39: INK-2204 | F39: PET | G39: Adhesion/Delamination | H39: Minor | I39: Open | K39: 0
A40: CMP-036 | B40: 46142 | C40: Bharat Snacks Ltd | D40: SKU-C Detergent Pouch | E40: INK-2203 | F40: PET | G40: Odor/Taint | H40: Major | I40: Closed | J40: 18 | K40: 16193
A41: CMP-037 | B41: 46198 | C41: SpiceKing Foods | D41: SKU-B Pet Food Pouch | E41: INK-2204 | F41: PET | G41: Adhesion/Delamination | H41: Major | I41: Closed | J41: 10 | K41: 31070
...

Sheet Complaint Analysis
A1: Complaint Pareto — by Count and by Cost
A2: Which complaint category is most frequent vs which is most expensive can differ — both matter
A4: Complaint Category | B4: Count | C4: % of Total | D4: Total Credit Notes (INR) | E4: % of Total Cost
A5: Adhesion/Delamination | B5: =COUNTIF('Complaint Log'!$G$5:$G$44,A5) -> 21 | C5: =B5/SUM($B$5:$B$10) -> 0.525 | D5: =SUMIF('Complaint Log'!$G$5:$G$44,A5,'Complaint Log'!$K$5:$K$44) -> 436641 | E5: =D5/SUM($D$5:$D$10) -> 0.50562785
A6: Color Mismatch | B6: =COUNTIF('Complaint Log'!$G$5:$G$44,A6) -> 3 | C6: =B6/SUM($B$5:$B$10) -> 0.075 | D6: =SUMIF('Complaint Log'!$G$5:$G$44,A6,'Complaint Log'!$K$5:$K$44) -> 6601 | E6: =D6/SUM($D$5:$D$10) -> 0.0076439213
A7: Odor/Taint | B7: =COUNTIF('Complaint Log'!$G$5:$G$44,A7) -> 8 | C7: =B7/SUM($B$5:$B$10) -> 0.2 | D7: =SUMIF('Complaint Log'!$G$5:$G$44,A7,'Complaint Log'!$K$5:$K$44) -> 343789 | E7: =D7/SUM($D$5:$D$10) -> 0.39810575
A8: Print Smudge/Scuff | B8: =COUNTIF('Complaint Log'!$G$5:$G$44,A8) -> 3 | C8: =B8/SUM($B$5:$B$10) -> 0.075 | D8: =SUMIF('Complaint Log'!$G$5:$G$44,A8,'Complaint Log'!$K$5:$K$44) -> 39190 | E8: =D8/SUM($D$5:$D$10) -> 0.045381802
A9: Migration/Compliance Query | B9: =COUNTIF('Complaint Log'!$G$5:$G$44,A9) -> 3 | C9: =B9/SUM($B$5:$B$10) -> 0.075 | D9: =SUMIF('Complaint Log'!$G$5:$G$44,A9,'Complaint Log'!$K$5:$K$44) -> 30755 | E9: =D9/SUM($D$5:$D$10) -> 0.035614119
A10: Viscosity/Print Defect | B10: =COUNTIF('Complaint Log'!$G$5:$G$44,A10) -> 2 | C10: =B10/SUM($B$5:$B$10) -> 0.05 | D10: =SUMIF('Complaint Log'!$G$5:$G$44,A10,'Complaint Log'!$K$5:$K$44) -> 6586 | E10: =D10/SUM($D$5:$D$10) -> 0.0076265514
A13: Monthly Complaint Trend
A14: Month | B14: Complaints | C14: Total Credit Notes (INR)
A15: Apr-2026 | B15: =SUMPRODUCT((MONTH('Complaint Log'!$B$5:$B$44)=4)*1) -> 7 | C15: =SUMPRODUCT((MONTH('Complaint Log'!$B$5:$B$44)=4)*'Complaint Log'!$K$5:$K$44) -> 146690
A16: May-2026 | B16: =SUMPRODUCT((MONTH('Complaint Log'!$B$5:$B$44)=5)*1) -> 11 | C16: =SUMPRODUCT((MONTH('Complaint Log'!$B$5:$B$44)=5)*'Complaint Log'!$K$5:$K$44) -> 225491
A17: Jun-2026 | B17: =SUMPRODUCT((MONTH('Complaint Log'!$B$5:$B$44)=6)*1) -> 6 | C17: =SUMPRODUCT((MONTH('Complaint Log'!$B$5:$B$44)=6)*'Complaint Log'!$K$5:$K$44) -> 72819
A18: Jul-2026 | B18: =SUMPRODUCT((MONTH('Complaint Log'!$B$5:$B$44)=7)*1) -> 6 | C18: =SUMPRODUCT((MONTH('Complaint Log'!$B$5:$B$44)=7)*'Complaint Log'!$K$5:$K$44) -> 156835
A19: Aug-2026 | B19: =SUMPRODUCT((MONTH('Complaint Log'!$B$5:$B$44)=8)*1) -> 5 | C19: =SUMPRODUCT((MONTH('Complaint Log'!$B$5:$B$44)=8)*'Complaint Log'!$K$5:$K$44) -> 80455
A20: Sep-2026 | B20: =SUMPRODUCT((MONTH('Complaint Log'!$B$5:$B$44)=9)*1) -> 5 | C20: =SUMPRODUCT((MONTH('Complaint Log'!$B$5:$B$44)=9)*'Complaint Log'!$K$5:$K$44) -> 181272
A22: A category can be #1 by count but not by cost (or vice versa) — Pareto by cost tells the CFO story, Pareto by count tells the QA workload story.

Sheet Root Cause Cross-Tab
A1: Which Ink Batch or Customer Is Driving Complaints?
A2: Cross-tab of complaint count and average resolution time by ink batch and by customer
A4: By Ink Batch
A5: Ink Batch | B5: Total Complaints | C5: Critical/Major | D5: Avg Resolution Days
A6: INK-2201 | B6: =COUNTIF('Complaint Log'!$E$5:$E$44,A6) -> 11 | C6: =COUNTIFS('Complaint Log'!$E$5:$E$44,A6,'Complaint Log'!$H$5:$H$44,"<>Minor") -> 4 | D6: =IFERROR(AVERAGEIFS('Complaint Log'!$J$5:$J$44,'Complaint Log'!$E$5:$E$44,A6,'Complaint Log'!$I$5:$I$44,"Closed"),0) -> 15
A7: INK-2202 | B7: =COUNTIF('Complaint Log'!$E$5:$E$44,A7) -> 6 | C7: =COUNTIFS('Complaint Log'!$E$5:$E$44,A7,'Complaint Log'!$H$5:$H$44,"<>Minor") -> 2 | D7: =IFERROR(AVERAGEIFS('Complaint Log'!$J$5:$J$44,'Complaint Log'!$E$5:$E$44,A7,'Complaint Log'!$I$5:$I$44,"Closed"),0) -> 12.333333
A8: INK-2203 | B8: =COUNTIF('Complaint Log'!$E$5:$E$44,A8) -> 3 | C8: =COUNTIFS('Complaint Log'!$E$5:$E$44,A8,'Complaint Log'!$H$5:$H$44,"<>Minor") -> 3 | D8: =IFERROR(AVERAGEIFS('Complaint Log'!$J$5:$J$44,'Complaint Log'!$E$5:$E$44,A8,'Complaint Log'!$I$5:$I$44,"Closed"),0) -> 12
A9: INK-2204 | B9: =COUNTIF('Complaint Log'!$E$5:$E$44,A9) -> 12 | C9: =COUNTIFS('Complaint Log'!$E$5:$E$44,A9,'Complaint Log'!$H$5:$H$44,"<>Minor") -> 10 | D9: =IFERROR(AVERAGEIFS('Complaint Log'!$J$5:$J$44,'Complaint Log'!$E$5:$E$44,A9,'Complaint Log'!$I$5:$I$44,"Closed"),0) -> 15.666667
A10: INK-2205 | B10: =COUNTIF('Complaint Log'!$E$5:$E$44,A10) -> 8 | C10: =COUNTIFS('Complaint Log'!$E$5:$E$44,A10,'Complaint Log'!$H$5:$H$44,"<>Minor") -> 3 | D10: =IFERROR(AVERAGEIFS('Complaint Log'!$J$5:$J$44,'Complaint Log'!$E$5:$E$44,A10,'Complaint Log'!$I$5:$I$44,"Closed"),0) -> 13
A13: By Customer
A14: Customer | B14: Total Complaints | C14: Total Credit Notes (INR) | D14: Avg Resolution Days
A15: Bharat Snacks Ltd | B15: =COUNTIF('Complaint Log'!$C$5:$C$44,A15) -> 6 | C15: =SUMIF('Complaint Log'!$C$5:$C$44,A15,'Complaint Log'!$K$5:$K$44) -> 139621 | D15: =IFERROR(AVERAGEIFS('Complaint Log'!$J$5:$J$44,'Complaint Log'!$C$5:$C$44,A15,'Complaint Log'!$I$5:$I$44,"Closed"),0) -> 18.5
A16: Nutri Foods Pvt Ltd | B16: =COUNTIF('Complaint Log'!$C$5:$C$44,A16) -> 5 | C16: =SUMIF('Complaint Log'!$C$5:$C$44,A16,'Complaint Log'!$K$5:$K$44) -> 59108 | D16: =IFERROR(AVERAGEIFS('Complaint Log'!$J$5:$J$44,'Complaint Log'!$C$5:$C$44,A16,'Complaint Log'!$I$5:$I$44,"Closed"),0) -> 13
A17: CleanCare Chemicals | B17: =COUNTIF('Complaint Log'!$C$5:$C$44,A17) -> 9 | C17: =SUMIF('Complaint Log'!$C$5:$C$44,A17,'Complaint Log'!$K$5:$K$44) -> 212120 | D17: =IFERROR(AVERAGEIFS('Complaint Log'!$J$5:$J$44,'Complaint Log'!$C$5:$C$44,A17,'Complaint Log'!$I$5:$I$44,"Closed"),0) -> 11.333333
A18: Fresh Dairy Co | B18: =COUNTIF('Complaint Log'!$C$5:$C$44,A18) -> 9 | C18: =SUMIF('Complaint Log'!$C$5:$C$44,A18,'Complaint Log'!$K$5:$K$44) -> 244269 | D18: =IFERROR(AVERAGEIFS('Complaint Log'!$J$5:$J$44,'Complaint Log'!$C$5:$C$44,A18,'Complaint Log'!$I$5:$I$44,"Closed"),0) -> 15.285714
A19: SpiceKing Foods | B19: =COUNTIF('Complaint Log'!$C$5:$C$44,A19) -> 5 | C19: =SUMIF('Complaint Log'!$C$5:$C$44,A19,'Complaint Log'!$K$5:$K$44) -> 66344 | D19: =IFERROR(AVERAGEIFS('Complaint Log'!$J$5:$J$44,'Complaint Log'!$C$5:$C$44,A19,'Complaint Log'!$I$5:$I$44,"Closed"),0) -> 11.666667
A20: PetNutrition India | B20: =COUNTIF('Complaint Log'!$C$5:$C$44,A20) -> 6 | C20: =SUMIF('Complaint Log'!$C$5:$C$44,A20,'Complaint Log'!$K$5:$K$44) -> 142100 | D20: =IFERROR(AVERAGEIFS('Complaint Log'!$J$5:$J$44,'Complaint Log'!$C$5:$C$44,A20,'Complaint Log'!$I$5:$I$44,"Closed"),0) -> 11.75
A22: If one ink batch shows up disproportionately across multiple customers' complaints, that batch (not each customer's process) is the common root cause.

Sheet Copilot Prompts
A1: How Technical/QA Used Copilot to Build This Complaint Model
A2: Training reference: prompt sequence and what Copilot generated
A4: Step | B4: Prompt Typed Into Copilot | C4: What Copilot Built / Which Cells
A5: 1 | B5: From this complaint log, count complaints by category and separately total the credit notes by category, each as a % of total. | C5: 'Complaint Analysis'!A5:E10 — COUNTIF and SUMIF per category, with a combo chart comparing count vs cost.
A6: 2 | B6: Show me the monthly trend of complaint count and credit note value from April to September. | C6: 'Complaint Analysis'!A15:C21 — SUMPRODUCT with a MONTH() condition, one row per month.
A7: 3 | B7: Break down total complaints, critical/major complaints, and average resolution time by ink batch, and separately by customer. | C7: 'Root Cause Cross-Tab'!A5:D14 — COUNTIF/COUNTIFS/AVERAGEIFS cross-tabs for batch and customer.
A8: 4 | B8: Which ink batch appears across the most different customers' complaints? That's likely a manufacturing root cause, not a customer-specific issue. | C8: Read directly off the Root Cause Cross-Tab table above — Copilot can also write a one-line summary sentence naming the batch with the highest complaint count.
